# 1. 异常

## 1.1 介绍

程序执行中难免出现异常, 如果出现异常, 程序就无法向下执行, 会直接中断. 

有没有一种方式可以将异常拦截, 并导入到文件中保存, 用于后期查错?

## 1.2 作用

* 提前预防程序出错, 拦截bug, 增强程序的稳定性, 出现bug照常运行.
* 获取详细错误信息
* 版本兼容

```python
try:
    预防代码
except ValueError, Exception as e:
    捕获到异常后, 错误信息存放在e中
except BaseException as e:
    可以多次选择性捕获异常
else:
    正常执行后
finally:
    最终必须执行
```

**注意**: 

* `finally`为必执行代码, 如果`finally`中有`return`, 则会跳过其他部分的: 异常, `return`等

**示例**

```python
def foo():
    try:
        return 1  # 此处如果有异常, 也不会抛出, 将会直接跳过
    finally:
        return 2

print(foo())   # 2
```



# 2. 异常抛出

## 2.1 raise

常用与手动抛出异常

```python
raise Exception("This is Exception Error")
```

输出

```python
Traceback (most recent call last):
  File "E:/project/test/t_builtins/test.py", line 213, in <module>
    raise Exception("This is Exception Error")
Exception: This is Exception Error
```

## 2.2 `raise from`

如果异常埋的太深的话, 用此方法来解释当前异常

`raise Error1 from Error2`, 表示异常`Error2`是来自于`Error1`

```python
raise Exception("This is Exception Error") from BaseException("This is BaseException Error")
```

输出

```python
BaseException: This is BaseException Error
The above exception was the direct cause of the following exception:
Traceback (most recent call last):
  File "E:/project/code/test/test1.py", line 4, in <module>
    raise Exception("This is Exception Error") from BaseException("This is BaseException Error")
Exception: This is Exception Error
```

## 2.3 assert

常用于**推测某种结果**, 如果推测为假, 则抛出异常

```python
assert 条件[, 异常内容]
```

此代码等价于:

```python
if __debug__:
    if not 条件:
        raise AssertionError(异常内容)
```

* `__debug__`: Python启动时的参数`-o`可以配置. 返回的结果都为True.

# 4. 异常类

## 4.1 自定义异常

```python
class Exception1(BaseException):
    """"""

    def __init__(self, message):
        self.message = message


class Exception2(BaseException):
    """"""

    def __init__(self, msg):
        self.msg = msg

    def __str__(self):
        return self.msg


if __name__ == '__main__':
    try:
        1 / 0
    except Exception:
        import sys
        tb = sys.exc_info()[-1]
        print(sys.exc_info())
        raise Exception1("111").with_traceback(tb)
```

## 4.2 内置异常类

| 序号 | 异常类              | 含义               | 基类            | 序号 | 异常类              | 含义                     | 基类             |
| ---- | ------------------- | ------------------ | --------------- | ---- | ------------------- | ------------------------ | ---------------- |
| 1    | BaseException       | 所有内置异常的基类 |                 | 16   | MemoryError         | 内存耗尽异常             | Exception        |
| 2    | Exception           | 内置异常类         | BaseException   | 17   | NameError           | 变量名不存在异常         | Exception        |
| 3    | ArithmeticError     | 算数异常类         | Exception       | 18   | NotImplementedError | 抽象基类控制的方法未添加 | RuntimeError     |
| 4    | BufferError         | 缓冲异常类         | Exception       | 19   | OSError             | IO操作异常               | Exception        |
| 5    | LookupError         | 键值异常类         | Exception       | 20   | OverflowError       | 算数运算结果超限         | ArithmeticError  |
| 6    | AssertionError      | 断言异常           | Exception       | 21   | RecursionError      | 递归超限                 | RuntimeError     |
| 7    | AttributeError      | 属性异常           | Exception       | 22   | ReferenceError      | 引用被垃圾回收的类       | Exception        |
| 8    | EOFError            | 文件读取中断异常   | Exception       | 23   | RuntimeError        | 其他类型的异常           | Exception        |
| 9    | FloatingPointError  | 浮点数操作异常     | ArithmeticError | 24   | StopIteration       | 迭代器调用停止异常       | BaseException    |
| 10   | GeneratorExit       | 生成器异常退出     | BaseException   | 25   | StopAsyncIteration  | 异步迭代器调用停止异常   | BaseException    |
| 11   | ImportError         | 模块导入异常       | Exception       | 26   | SyntaxError         | 语法错误                 | Exception        |
| 12   | ModuleNotFoundError | 未找到模块导入异常 | ImportError     | 27   | IndentationError    | 缩进异常                 | SyntaxError      |
| 13   | IndexError          | 索引异常           | LookupError     | 28   | TabError            | 缩进标识符不一致         | IndentationError |
| 14   | KeyError            | 键值错误           | LookupError     | 29   | SystemError         | 解释器内部错误           | Exception        |
| 15   | KeyboardInterrupt   | ctrl+c退出         | BaseException   | 30   | SystemExit          | sys.exit()退出           | BaseException    |

| 序号 | 异常类                 | 含义                     | 基类            | 序号 | 异常类                    | 含义                       | 基类            |
| ---- | ---------------------- | ------------------------ | --------------- | ---- | ------------------------- | -------------------------- | --------------- |
| 31   | TypeError              | 类型异常                 | Exception       | 46   | ConnectionRefusedError    | 网络连接对方拒绝访问       | ConnectionError |
| 32   | UnboundLocalError      | 局部变量未定义前使用     | NameError       | 47   | ConnectionResetError      | 网络连接对方重置访问       | ConnectionError |
| 33   | UnicodeError           | 编解码Unicode异常        | ValueError      | 48   | FileExistsError           | 文件存在异常               | OSError         |
| 34   | UnicodeEncodeError     | 编码Unicode异常          | UnicodeError    | 49   | FileNotFoundError         | 文件不存在异常             | OSError         |
| 35   | UnicodeDecodeError     | 解码Unicode异常          | UnicodeError    | 50   | InterruptedError          | 系统输入中断               | OSError         |
| 36   | UnicodeTranslateError  | Unicode转换异常          | ValueError      | 51   | IsADirectoryError         | 目录操作函数传递了文件     | OSError         |
| 37   | ValueError             | 参数传递出错             | Exception       | 52   | NotADirectoryError        | 文件操作函数传递了目录     | OSError         |
| 38   | ZeroDivisionError      | 除0异常                  | ArithmeticError | 53   | PermissionError           | 权限不足                   | OSError         |
| 39   | EnvironmentError       | 环境读取异常             | Exception       | 54   | ProcessLookupError        | 进程不存在                 | OSError         |
| 40   | WindowsError           | window异常               | Exception       | 55   | TimeoutError              | 超时异常                   | OSError         |
| 41   | BlockingIOError        | 解除阻塞状态异常         | OSError         | 56   | Warning                   | 警告基类                   | Exception       |
| 42   | ChildProcessError      | 子进程执行失败异常       | OSError         | 57   | UserWarning               | 用户代码警告               | Warning         |
| 43   | ConnectionError        | 连接异常                 | OSError         | 58   | DeprecationWarning        | Python开发者警告(模块弃用) | Warning         |
| 44   | BrokenPipeError        | 被关闭管道的写入异常     | ConnectionError | 59   | PendingDeprecationWarning | 模块即将弃用警告           | Warning         |
| 45   | ConnectionAbortedError | 网络连接对方强制中止异常 | ConnectionError | 60   | SyntaxWarning             | 语法警告                   | Warning         |



| 序号 | 异常类          | 含义                     | 基类    | 序号 | 异常类 | 含义 | 基类 |
| ---- | --------------- | ------------------------ | ------- | ---- | ------ | ---- | ---- |
| 61   | RuntimeWarning  | 模糊运行行为警告         | Warning |      |        |      |      |
| 62   | FutureWarning   | Python用户警告(模块弃用) | Warning |      |        |      |      |
| 63   | ImportWarning   | 模块导入可能失败警告     | Warning |      |        |      |      |
| 64   | UnicodeWarning  | Unicode警告基类          | Warning |      |        |      |      |
| 65   | BytesWarning    | bytes/bytearray警告基类  | Warning |      |        |      |      |
| 66   | ResourceWarning | 使用的资源警告           | Warning |      |        |      |      |